Workbook

Sheet M2-5
E1: Room 2114 | J1: | | O1: Room 2122 | T1: | | Y1: Room 2115 | AD1: | | AI1: Room 2123
A2: Pot | B2: # oat | C2: avg length (mm) | D2: avg weight (mg) | E2: tot weight (g) | F2: # tom | G2: avg length (mm) | H2: avg weight (mg) | I2: tot weight (g) | K2: Pot | L2: # oat | M2: avg length (mm) | N2: avg weight (mg) | O2: tot weight (g) | P2: # tom | Q2: avg length (mm) | R2: avg weight (mg) | S2: tot weight (g) | U2: Pot | V2: # oat | W2: avg length (mm) | X2: avg weight (mg) | Y2: tot weight (g) | Z2: # tom | AA2: avg length (mm) | AB2: avg weight (mg) | AC2: tot weight (g) | AE2: Pot | AF2: # oat | AG2: avg length (mm) | AH2: avg weight (mg) | AI2: tot weight (g) | AJ2: # tom | AK2: avg length (mm) | AL2: avg weight (mg) | AM2: tot weight (g)
A3: ------/30 tom | F3: 30 | G3: 39.43 | H3: 43.66 | I3: 1.31 | K3: ------/30 tom | P3: 21 | Q3: 104.67 | R3: 722.38 | S3: 15.17 | U3: ------/30 tom | Z3: 24 | AA3: 60.8 | AB3: 130 | AC3: 3.12 | AE3: ------/30 tom | AJ3: 23 | AK3: 49.7 | AL3: 123.9 | AM3: 2.85
A4: 10 oat/20 tom | B4: 10 | C4: 182.3 | D4: 180 | E4: 1.8 | F4: 12 | G4: 41.16 | H4: 90.83 | I4: 1.09 | K4: 10 oat/20 tom | L4: 11 | M4: 306.36 | N4: 1038.18 | O4: 11.42 | P4: 12 | Q4: 65.83 | R4: 124.17 | S4: 1.49 | U4: 10 oat/20 tom | V4: 10 | W4: 272.3 | X4: 567 | Y4: 5.67 | Z4: 19 | AA4: 53.8 | AB4: 78.9 | AC4: 1.5 | AE4: 10 oat/20 tom | AF4: 10 | AG4: 253.8 | AH4: 729 | AI4: 7.29 | AJ4: 18 | AK4: 51.27 | AL4: 80.55 | AM4: 1.45
A5: 20 oat/10 tom | B5: 20 | C5: 156.6 | D5: 172.5 | E5: 3.45 | F5: 10 | G5: 45.2 | H5: 46 | I5: 0.46 | K5: 20 oat/10 tom | L5: 20 | M5: 296 | N5: 976 | O5: 19.52 | P5: 1 | Q5: 74 | R5: 170 | S5: 0.17 | U5: 20 oat/10 tom | V5: 18 | W5: 249 | X5: 476 | Y5: 8.57 | Z5: 6 | AA5: 40 | AB5: 50 | AC5: 0.3 | AE5: 20 oat/10 tom | AF5: 17 | AG5: 227.6 | AH5: 461.8 | AI5: 7.85 | AJ5: 10 | AK5: 46.5 | AL5: 67 | AM5: 0.67
A6: 30 oat/------ | B6: 40 | C6: 166.88 | D6: 195.25 | E6: 7.81 | K6: 30 oat/------ | L6: 27 | M6: 251.74 | N6: 741.11 | O6: 20.01 | U6: 30 oat/------ | V6: 30 | W6: 234.2 | X6: 139 | Y6: 4.17 | AE6: 30 oat/------ | AF6: 27 | AG6: 238.4 | AH6: 498.9 | AI6: 13.47
A8: Pot | B8: # oat | C8: avg length (mm) | D8: avg weight (mg) | E8: tot weight (g) | F8: # alf | G8: avg length (mm) | H8: avg weight (mg) | I8: tot weight (g) | K8: Pot | L8: # oat | M8: avg length (mm) | N8: avg weight (mg) | O8: tot weight (g) | P8: # alf | Q8: avg length (mm) | R8: avg weight (mg) | S8: tot weight (g) | U8: Pot | V8: # oat | W8: avg length (mm) | X8: avg weight (mg) | Y8: tot weight (g) | Z8: # alf | AA8: avg length (mm) | AB8: avg weight (mg) | AC8: tot weight (g) | AE8: Pot | AF8: # oat | AG8: avg length (mm) | AH8: avg weight (mg) | AI8: tot weight (g) | AJ8: # alf | AK8: avg length (mm) | AL8: avg weight (mg) | AM8: tot weight (g)
A9: ------/30 alf | F9: 44 | G9: 54.17 | H9: 172 | I9: 7.57 | K9: ------/30 alf | P9: 5 | Q9: 58.6 | R9: 164 | S9: 0.82 | U9: ------/30 alf | Z9: 17 | AA9: 63 | AB9: 139 | AC9: 2.37 | AE9: ------/30 alf | AJ9: 12 | AK9: 54.6 | AL9: 99.16 | AM9: 1.19
A10: 10 oat/20 alf | B10: 10 | C10: 178.1 | D10: 176 | E10: 1.76 | F10: 35 | G10: 53.09 | H10: 176 | I10: 4.61 | K10: 10 oat/20 alf | L10: 9 | M10: 313.33 | N10: 1020 | O10: 9.18 | P10: 9 | Q10: 58.33 | R10: 75.56 | S10: 0.68 | U10: 10 oat/20 alf | V10: 9 | W10: 339.56 | X10: 855.6 | Y10: 7.7 | Z10: 11 | AA10: 50.09 | AB10: 93.6 | AC10: 1.03 | AE10: 10 oat/20 alf | AF10: 9 | AG10: 249.4 | AH10: 680 | AI10: 6.12 | AJ10: 10 | AK10: 56.2 | AL10: 126 | AM10: 1.26
A11: 20 oat/10 alf | B11: 20 | C11: 171.7 | D11: 169.5 | E11: 3.39 | F11: 16 | G11: 42.125 | H11: 71.25 | I11: 1.14 | K11: 20 oat/10 alf | L11: 19 | M11: 280.6 | N11: 940 | O11: 17.88 | P11: 6 | Q11: 30.16 | R11: 46 | S11: 0.28 | U11: 20 oat/10 alf | V11: 20 | W11: 244.15 | X11: 473.5 | Y11: 9.47 | Z11: 9 | AA11: 47.78 | AB11: 93.34 | AC11: 0.84 | AE11: 20 oat/10 alf | AF11: 20 | AG11: 212.8 | AH11: 350 | AI11: 7 | AJ11: 7 | AK11: 30.43 | AL11: 64.29 | AM11: 0.45
A12: 30 oat/------ | B12: 40 | C12: 166.88 | D12: 195.25 | E12: 7.81 | K12: 30 oat/------ | L12: 27 | M12: 251.74 | N12: 741.11 | O12: 20.01 | U12: 30 oat/------ | V12: 30 | W12: 234.2 | X12: 139 | Y12: 4.17 | AE12: 30 oat/------ | AF12: 27 | AG12: 238.4 | AH12: 498.9 | AI12: 13.47
A14: Pot | B14: # tom | C14: avg length (mm) | D14: avg weight (mg) | E14: tot weight (g) | F14: # alf | G14: avg length (mm) | H14: avg weight (mg) | I14: tot weight (g) | K14: Pot | L14: # tom | M14: avg length (mm) | N14: avg weight (mg) | O14: tot weight (g) | P14: # alf | Q14: avg length (mm) | R14: avg weight (mg) | S14: tot weight (g) | U14: Pot | V14: # tom | W14: avg length (mm) | X14: avg weight (mg) | Y14: tot weight (g) | Z14: # alf | AA14: avg length (mm) | AB14: avg weight (mg) | AC14: tot weight (g) | AE14: Pot | AF14: # tom | AG14: avg length (mm) | AH14: avg weight (mg) | AI14: tot weight (g) | AJ14: # alf | AK14: avg length (mm) | AL14: avg weight (mg) | AM14: tot weight (g)
A15: ------ /30 alf | F15: 44 | G15: 54.17 | H15: 172 | I15: 7.57 | K15: ------ /30 alf | P15: 5 | Q15: 58.6 | R15: 164 | S15: 0.82 | U15: ------ /30 alf | Z15: 17 | AA15: 63 | AB15: 139 | AC15: 2.37 | AE15: ------ /30 alf | AJ15: 12 | AK15: 54.6 | AL15: 99.16 | AM15: 1.19
A16: 10 tom /20 alf | B16: 14 | C16: 29.5 | D16: 34.28 | E16: 0.48 | F16: 12 | G16: 59.17 | H16: 171.67 | I16: 2.06 | K16: 10 tom /20 alf | L16: 7 | M16: 119.28 | N16: 1224.3 | O16: 8.57 | P16: 9 | Q16: 50.88 | R16: 128.88 | S16: 1.16 | U16: 10 tom /20 alf | V16: 8 | W16: 80 | X16: 230 | Y16: 1.84 | Z16: 15 | AA16: 63.46 | AB16: 146.7 | AC16: 2.2 | AE16: 10 tom /20 alf | AF16: 4 | AG16: 40.25 | AH16: 40 | AI16: 0.16 | AJ16: 10 | AK16: 49.2 | AL16: 104 | AM16: 1.04
A17: 20 tom /10 alf | B17: 40 | C17: 39.95 | D17: 56.5 | E17: 2.26 | F17: 10 | G17: 58.8 | H17: 121 | I17: 1.21 | K17: 20 tom /10 alf | L17: 8 | M17: 136.63 | N17: 1051.3 | O17: 8.41 | P17: 7 | Q17: 45.57 | R17: 92.86 | S17: 0.65 | U17: 20 tom /10 alf | V17: 14 | W17: 57 | X17: 131.4 | Y17: 1.84 | Z17: 7 | AA17: 104 | AB17: 238.6 | AC17: 1.67 | AE17: 20 tom /10 alf | AF17: 10 | AG17: 47.3 | AH17: 78 | AI17: 0.78 | AJ17: 3 | AK17: 55 | AL17: 103.3 | AM17: 0.31
A18: 30 tom /------ | B18: 30 | C18: 39.43 | D18: 43.66 | E18: 1.31 | K18: 30 tom /------ | L18: 21 | M18: 104.67 | N18: 722.38 | O18: 15.17 | U18: 30 tom /------ | V18: 24 | W18: 60.8 | X18: 130 | Y18: 3.12 | AE18: 30 tom /------ | AF18: 23 | AG18: 49.7 | AH18: 123.9 | AI18: 2.85
A20: note- data for each monoculture pot must be entered in two places above

Sheet M7-10
E1: Room 2114 | J1: | | O1: Room 2122 | T1: | | Y1: Room 2115 | AD1: | | AI1: Room 2123
A2: Pot | B2: # oat | C2: avg length (mm) | D2: avg weight (mg) | E2: tot weight (g) | F2: # tom | G2: avg length (mm) | H2: avg weight (mg) | I2: tot weight (g) | K2: Pot | L2: # oat | M2: avg length (mm) | N2: avg weight (mg) | O2: tot weight (g) | P2: # tom | Q2: avg length (mm) | R2: avg weight (mg) | S2: tot weight (g) | U2: Pot | V2: # oat | W2: avg length (mm) | X2: avg weight (mg) | Y2: tot weight (g) | Z2: # tom | AA2: avg length (mm) | AB2: avg weight (mg) | AC2: tot weight (g) | AE2: Pot | AF2: # oat | AG2: avg length (mm) | AH2: avg weight (mg) | AI2: tot weight (g) | AJ2: # tom | AK2: avg length (mm) | AL2: avg weight (mg) | AM2: tot weight (g)
A3: ------/30 tom | F3: 40 | G3: 42.75 | H3: 54.75 | I3: 2.19 | K3: ------/30 tom | P3: 40 | Q3: 59.2 | R3: 267.75 | S3: 10.71 | U3: ------/30 tom | Z3: 30 | AA3: 89.47 | AB3: 109 | AC3: 3.27 | AE3: ------/30 tom | AJ3: 25 | AK3: 61.32 | AL3: 135.6 | AM3: 3.39
A4: 10 oat/20 tom | B4: 15 | C4: 177.13 | D4: 202 | E4: 3.03 | F4: 26 | G4: 40.88 | H4: 65.38 | I4: 1.7 | K4: 10 oat/20 tom | L4: 10 | M4: 178.5 | N4: 186 | O4: 1.86 | P4: 20 | Q4: 58.45 | R4: 138.5 | S4: 2.77 | U4: 10 oat/20 tom | V4: 10 | W4: 237.1 | X4: 625 | Y4: 6.25 | Z4: 20 | AA4: 64.8 | AB4: 59.5 | AC4: 1.19 | AE4: 10 oat/20 tom | AF4: 10 | AG4: 266.1 | AH4: 614 | AI4: 6.14 | AJ4: 14 | AK4: 58.28 | AL4: 102.86 | AM4: 1.44
A5: 20 oat/10 tom | B5: 16 | C5: 160 | D5: 184.375 | E5: 2.95 | F5: 16 | G5: 33.25 | H5: 39.375 | I5: 0.63 | K5: 20 oat/10 tom | L5: 34 | M5: 196.4 | N5: 204.41 | O5: 6.95 | P5: 39 | Q5: 40.66 | R5: 38.97 | S5: 1.52 | U5: 20 oat/10 tom | V5: 20 | W5: 225.7 | X5: 474 | Y5: 9.48 | Z5: 10 | AA5: 59.4 | AB5: 69 | AC5: 0.69 | AE5: 20 oat/10 tom | AF5: 19 | AG5: 246.95 | AH5: 507.89 | AI5: 9.65 | AJ5: 8 | AK5: 51 | AL5: 65 | AM5: 0.52
A6: 30 oat/------ | B6: 40 | C6: 180.74 | D6: 197.25 | E6: 7.89 | K6: 30 oat/------ | L6: 40 | M6: 186.775 | N6: 206.5 | O6: 8.26 | U6: 30 oat/------ | V6: 40 | W6: 225.3 | X6: 225 | Y6: 9 | AE6: 30 oat/------ | AF6: 30 | AG6: 216.56 | AH6: 425 | AI6: 12.75
A8: Pot | B8: # oat | C8: avg length (mm) | D8: avg weight (mg) | E8: tot weight (g) | F8: # alf | G8: avg length (mm) | H8: avg weight (mg) | I8: tot weight (g) | K8: Pot | L8: # oat | M8: avg length (mm) | N8: avg weight (mg) | O8: tot weight (g) | P8: # alf | Q8: avg length (mm) | R8: avg weight (mg) | S8: tot weight (g) | U8: Pot | V8: # oat | W8: avg length (mm) | X8: avg weight (mg) | Y8: tot weight (g) | Z8: # alf | AA8: avg length (mm) | AB8: avg weight (mg) | AC8: tot weight (g) | AE8: Pot | AF8: # oat | AG8: avg length (mm) | AH8: avg weight (mg) | AI8: tot weight (g) | AJ8: # alf | AK8: avg length (mm) | AL8: avg weight (mg) | AM8: tot weight (g)
A9: ------/30 alf | F9: 31 | G9: 55.51 | H9: 110.32 | I9: 3.42 | K9: ------/30 alf | P9: 39 | Q9: 54.43 | R9: 116.15 | S9: 4.53 | U9: ------/30 alf | Z9: 2 | AA9: 127.5 | AB9: 380 | AC9: 0.76 | AE9: ------/30 alf | AJ9: 19 | AK9: 81.32 | AL9: 160 | AM9: 3.04
A10: 10 oat/20 alf | B10: 32 | C10: 151.25 | D10: 72.906 | E10: 2.33 | F10: 40 | G10: 47.125 | H10: 86.75 | I10: 3.47 | K10: 10 oat/20 alf | L10: 10 | M10: 182.2 | N10: 280 | O10: 2.8 | P10: 13 | Q10: 5.29 | R10: 173.84 | S10: 2.26 | U10: 10 oat/20 alf | V10: 19 | W10: 192.05 | X10: 255.79 | Y10: 4.86 | Z10: 40 | AA10: 38.03 | AB10: 74.5 | AC10: 2.98 | AE10: 10 oat/20 alf | AF10: 9 | AG10: 335 | AH10: 838.89 | AI10: 7.55 | AJ10: 13 | AK10: 54.85 | AL10: 122.31 | AM10: 1.59
A11: 20 oat/10 alf | B11: 18 | C11: 169.27 | D11: 184.4 | E11: 3.32 | F11: 10 | G11: 59.5 | H11: 136 | I11: 1.36 | K11: 20 oat/10 alf | L11: 25 | M11: 177 | N11: 195.6 | O11: 4.89 | P11: 10 | Q11: 34 | R11: 60 | S11: 0.6 | U11: 20 oat/10 alf | V11: 20 | W11: 221.75 | X11: 322.5 | Y11: 6.45 | Z11: 8 | AA11: 37.75 | AB11: 38.75 | AC11: 0.31 | AE11: 20 oat/10 alf | AF11: 18 | AG11: 273.16 | AH11: 490.56 | AI11: 8.83 | AJ11: 7 | AK11: 25.23 | AL11: 30 | AM11: 0.21
A12: 30 oat/------ | B12: 40 | C12: 180.74 | D12: 197.25 | E12: 7.89 | K12: 30 oat/------ | L12: 40 | M12: 186.775 | N12: 206.5 | O12: 8.26 | U12: 30 oat/------ | V12: 40 | W12: 225.3 | X12: 225 | Y12: 9 | AE12: 30 oat/------ | AF12: 30 | AG12: 216.56 | AH12: 425 | AI12: 12.75
A14: Pot | B14: # tom | C14: avg length (mm) | D14: avg weight (mg) | E14: tot weight (g) | F14: # alf | G14: avg length (mm) | H14: avg weight (mg) | I14: tot weight (g) | K14: Pot | L14: # tom | M14: avg length (mm) | N14: avg weight (mg) | O14: tot weight (g) | P14: # alf | Q14: avg length (mm) | R14: avg weight (mg) | S14: tot weight (g) | U14: Pot | V14: # tom | W14: avg length (mm) | X14: avg weight (mg) | Y14: tot weight (g) | Z14: # alf | AA14: avg length (mm) | AB14: avg weight (mg) | AC14: tot weight (g) | AE14: Pot | AF14: # tom | AG14: avg length (mm) | AH14: avg weight (mg) | AI14: tot weight (g) | AJ14: # alf | AK14: avg length (mm) | AL14: avg weight (mg) | AM14: tot weight (g)
A15: ------ /30 alf | F15: 31 | G15: 55.51 | H15: 110.32 | I15: 3.42 | K15: ------ /30 alf | P15: 39 | Q15: 54.43 | R15: 116.15 | S15: 4.53 | U15: ------ /30 alf | Z15: 2 | AA15: 127.5 | AB15: 380 | AC15: 0.76 | AE15: ------ /30 alf | AJ15: 19 | AK15: 81.32 | AL15: 160 | AM15: 3.04
A16: 10 tom /20 alf | B16: 10 | C16: 27.4 | D16: 31 | E16: 0.31 | F16: 20 | G16: 42.35 | H16: 121 | I16: 2.42 | K16: 10 tom /20 alf | L16: 10 | M16: 42.2 | N16: 55 | O16: 0.55 | P16: 18 | Q16: 52.66 | R16: 149.44 | S16: 2.69 | U16: 10 tom /20 alf | V16: 10 | W16: 47.7 | X16: 88 | Y16: 0.88 | Z16: 20 | AA16: 44.95 | AB16: 92 | AC16: 1.84 | AE16: 10 tom /20 alf | AF16: 9 | AG16: 61.74 | AH16: 118.8 | AI16: 1.07 | AJ16: 11 | AK16: 95.36 | AL16: 230.9 | AM16: 2.54
A17: 20 tom /10 alf | B17: 37 | C17: 36.97 | D17: 36.22 | E17: 1.34 | F17: 19 | G17: 34.84 | H17: 48.95 | I17: 0.93 | K17: 20 tom /10 alf | L17: 27 | M17: 3.81 | N17: 51.85 | O17: 1.4 | P17: 14 | Q17: 4.51 | R17: 113.57 | S17: 1.59 | U17: 20 tom /10 alf | V17: 20 | W17: 56.05 | X17: 88.5 | Y17: 1.77 | Z17: 10 | AA17: 31.7 | AB17: 95.4 | AC17: 0.95 | AE17: 20 tom /10 alf | AF17: 13 | AG17: 61.84 | AH17: 130.77 | AI17: 1.7 | AJ17: 9 | AK17: 76.67 | AL17: 192.2 | AM17: 1.73
A18: 30 tom /------ | B18: 40 | C18: 42.75 | D18: 54.75 | E18: 2.19 | K18: 30 tom /------ | L18: 40 | M18: 59.2 | N18: 267.75 | O18: 10.71 | U18: 30 tom /------ | V18: 30 | W18: 89.47 | X18: 109 | Y18: 3.27 | AE18: 30 tom /------ | AF18: 25 | AG18: 61.32 | AH18: 135.6 | AI18: 3.39
A20: note- data for each monoculture pot must be entered in two places above

Sheet T9-12
E1: Room 2114 | J1: | | O1: Room 2122 | T1: | | Y1: Room 2115 | AD1: | | AI1: Room 2123
A2: Pot | B2: # oat | C2: avg length (mm) | D2: avg weight (mg) | E2: tot weight (g) | F2: # tom | G2: avg length (mm) | H2: avg weight (mg) | I2: tot weight (g) | K2: Pot | L2: # oat | M2: avg length (mm) | N2: avg weight (mg) | O2: tot weight (g) | P2: # tom | Q2: avg length (mm) | R2: avg weight (mg) | S2: tot weight (g) | U2: Pot | V2: # oat | W2: avg length (mm) | X2: avg weight (mg) | Y2: tot weight (g) | Z2: # tom | AA2: avg length (mm) | AB2: avg weight (mg) | AC2: tot weight (g) | AE2: Pot | AF2: # oat | AG2: avg length (mm) | AH2: avg weight (mg) | AI2: tot weight (g) | AJ2: # tom | AK2: avg length (mm) | AL2: avg weight (mg) | AM2: tot weight (g)
A3: ------/30 tom | F3: 13 | G3: 26.3846 | H3: 42.3 | I3: 0.55 | K3: ------/30 tom | P3: 23 | Q3: 45.08 | R3: 61.74 | S3: 1.42 | U3: ------/30 tom | Z3: 21 | AA3: 56.7 | AB3: 102.9 | AC3: 2.16 | AE3: ------/30 tom | AJ3: 26 | AK3: 63.73 | AL3: 118.08 | AM3: 3.07
A4: 10 oat/20 tom | B4: 10 | C4: 164.3 | D4: 202 | E4: 2.02 | F4: 11 | G4: 15.05 | H4: 20.9 | I4: 0.23 | K4: 10 oat/20 tom | L4: 9 | M4: 142.22 | N4: 150 | O4: 1.35 | P4: 13 | Q4: 32.31 | R4: 40 | S4: 0.52 | U4: 10 oat/20 tom | V4: 9 | W4: 263.8 | X4: 735.555 | Y4: 6.62 | Z4: 14 | AA4: 46.6 | AB4: 101.4 | AC4: 1.42 | AE4: 10 oat/20 tom | AF4: 10 | AG4: 235.5 | AH4: 480 | AI4: 4.8 | AJ4: 11 | AK4: 44.27 | AL4: 57.27 | AM4: 0.63
A5: 20 oat/10 tom | B5: 20 | C5: 158.4 | D5: 207.5 | E5: 4.15 | F5: 6 | G5: 25 | H5: 30 | I5: 0.18 | K5: 20 oat/10 tom | L5: 20 | M5: 161.45 | N5: 162 | O5: 3.24 | P5: 12 | Q5: 41.58 | R5: 40 | S5: 0.48 | U5: 20 oat/10 tom | V5: 20 | W5: 218 | X5: 414 | Y5: 8.28 | Z5: 7 | AA5: 40.9 | AB5: 71.4 | AC5: 0.5 | AE5: 20 oat/10 tom | AF5: 20 | AG5: 244.5 | AH5: 439.5 | AI5: 8.79 | AJ5: 7 | AK5: 38.7 | AL5: 57.1 | AM5: 0.4
A6: 30 oat/------ | B6: 29 | C6: 167.96 | D6: 158.8 | E6: 5.39 | K6: 30 oat/------ | L6: 29 | M6: 176.38 | N6: 173.45 | O6: 5.03 | U6: 30 oat/------ | V6: 28 | W6: 216.7 | X6: 358.2 | Y6: 10.03 | AE6: 30 oat/------ | AF6: 30 | AG6: 239.33 | AH6: 412.33 | AI6: 12.37
A8: Pot | B8: # oat | C8: avg length (mm) | D8: avg weight (mg) | E8: tot weight (g) | F8: # alf | G8: avg length (mm) | H8: avg weight (mg) | I8: tot weight (g) | K8: Pot | L8: # oat | M8: avg length (mm) | N8: avg weight (mg) | O8: tot weight (g) | P8: # alf | Q8: avg length (mm) | R8: avg weight (mg) | S8: tot weight (g) | U8: Pot | V8: # oat | W8: avg length (mm) | X8: avg weight (mg) | Y8: tot weight (g) | Z8: # alf | AA8: avg length (mm) | AB8: avg weight (mg) | AC8: tot weight (g) | AE8: Pot | AF8: # oat | AG8: avg length (mm) | AH8: avg weight (mg) | AI8: tot weight (g) | AJ8: # alf | AK8: avg length (mm) | AL8: avg weight (mg) | AM8: tot weight (g)
A9: ------/30 alf | F9: 20 | G9: 44.35 | H9: 95 | I9: 1.9 | K9: ------/30 alf | P9: 16 | Q9: 53.56 | R9: 156.25 | S9: 2.5 | U9: ------/30 alf | Z9: 19 | AA9: 50.95 | AB9: 127.9 | AC9: 2.4 | AE9: ------/30 alf | AJ9: 18 | AK9: 66.8 | AL9: 117.78 | AM9: 2.12
A10: 10 oat/20 alf | B10: 11 | C10: 173.73 | D10: 218 | E10: 2.4 | F10: 18 | G10: 48 | H10: 96 | I10: 1.34 | K10: 10 oat/20 alf | L10: 10 | M10: 182.9 | N10: 192 | O10: 1.92 | P10: 14 | Q10: 48.57 | R10: 92.86 | S10: 1.3 | U10: 10 oat/20 alf | V10: 9 | W10: 232.6 | X10: 488.9 | Y10: 4.4 | Z10: 9 | AA10: 78.4 | AB10: 216.7 | AC10: 1.95 | AE10: 10 oat/20 alf | AF10: 10 | AG10: 214.2 | AH10: 410 | AI10: 4.1 | AJ10: 16 | AK10: 68.12 | AL10: 171.25 | AM10: 2.74
A11: 20 oat/10 alf | B11: 21 | C11: 163.48 | D11: 168 | E11: 3.53 | F11: 4 | G11: 50 | H11: 103 | I11: 0.41 | K11: 20 oat/10 alf | L11: 19 | M11: 172 | N11: 184.74 | O11: 3.51 | P11: 4 | Q11: 76.75 | R11: 180 | S11: 0.72 | U11: 20 oat/10 alf | V11: 20 | W11: 247 | X11: 457 | Y11: 9.14 | Z11: 10 | AA11: 69.2 | AB11: 205 | AC11: 2.05 | AE11: 20 oat/10 alf | AF11: 19 | AG11: 210.82 | AH11: 341.053 | AI11: 6.48 | AJ11: 9 | AK11: 79.02 | AL11: 165.56 | AM11: 1.49
A12: 30 oat/------ | B12: 29 | C12: 167.96 | D12: 185.86 | E12: 5.39 | K12: 30 oat/------ | L12: 29 | M12: 176.38 | N12: 173.45 | O12: 5.03 | U12: 30 oat/------ | V12: 28 | W12: 216.7 | X12: 358.2 | Y12: 10.03 | AE12: 30 oat/------ | AF12: 30 | AG12: 239.33 | AH12: 412.33 | AI12: 12.37
A14: Pot | B14: # tom | C14: avg length (mm) | D14: avg weight (mg) | E14: tot weight (g) | F14: # alf | G14: avg length (mm) | H14: avg weight (mg) | I14: tot weight (g) | K14: Pot | L14: # tom | M14: avg length (mm) | N14: avg weight (mg) | O14: tot weight (g) | P14: # alf | Q14: avg length (mm) | R14: avg weight (mg) | S14: tot weight (g) | U14: Pot | V14: # tom | W14: avg length (mm) | X14: avg weight (mg) | Y14: tot weight (g) | Z14: # alf | AA14: avg length (mm) | AB14: avg weight (mg) | AC14: tot weight (g) | AE14: Pot | AF14: # tom | AG14: avg length (mm) | AH14: avg weight (mg) | AI14: tot weight (g) | AJ14: # alf | AK14: avg length (mm) | AL14: avg weight (mg) | AM14: tot weight (g)
A15: ------ /30 alf | F15: 20 | G15: 44.35 | H15: 95 | I15: 1.9 | K15: ------ /30 alf | P15: 16 | Q15: 53.56 | R15: 156.25 | S15: 2.5 | U15: ------ /30 alf | Z15: 19 | AA15: 50.95 | AB15: 127.9 | AC15: 2.4 | AE15: ------ /30 alf | AJ15: 18 | AK15: 66.8 | AL15: 117.78 | AM15: 2.12
A16: 10 tom /20 alf | B16: 4 | C16: 31.75 | D16: 35 | E16: 0.14 | F16: 12 | G16: 56.25 | H16: 162 | I16: 1.95 | K16: 10 tom /20 alf | L16: 6 | M16: 36 | N16: 48.3 | O16: 0.29 | P16: 10 | Q16: 59.1 | R16: 128 | S16: 1.28 | U16: 10 tom /20 alf | V16: 7 | W16: 48.4 | X16: 72.9 | Y16: 0.51 | Z16: 18 | AA16: 61.6 | AB16: 172.8 | AC16: 3.1 | AE16: 10 tom /20 alf | AF16: 6 | AG16: 49 | AH16: 138.3 | AI16: 0.83 | AJ16: 14 | AK16: 96.5 | AL16: 212.9 | AM16: 2.98
A17: 20 tom /10 alf | B17: 20 | C17: 33.55 | D17: 52.5 | E17: 1.05 | F17: 8 | G17: 37.875 | H17: 91 | I17: 0.73 | K17: 20 tom /10 alf | L17: 10 | M17: 33.2 | N17: 35 | O17: 0.35 | P17: 7 | Q17: 79.29 | R17: 261.43 | S17: 1.83 | U17: 20 tom /10 alf | V17: 17 | W17: 61.7 | X17: 81.18 | Y17: 1.4 | Z17: 9 | AA17: 65.4 | AB17: 148.9 | AC17: 1.34 | AE17: 20 tom /10 alf | AF17: 14 | AG17: 47.8 | AH17: 79.3 | AI17: 1.11 | AJ17: 5 | AK17: 92.2 | AL17: 212 | AM17: 1.06
A18: 30 tom /------ | B18: 13 | C18: 26.3846 | D18: 42.3 | E18: 0.55 | K18: 30 tom /------ | L18: 23 | M18: 45.08 | N18: 61.74 | O18: 1.42 | U18: 30 tom /------ | V18: 21 | W18: 56.7 | X18: 102.9 | Y18: 2.16 | AE18: 30 tom /------ | AF18: 26 | AG18: 63.73 | AH18: 118.08 | AI18: 3.07
A20: note- data for each monoculture pot must be entered in two places above

Sheet T2-5
E1: Room 2114 | J1: | | O1: Room 2122 | T1: | | Y1: Room 2115 | AD1: | | AI1: Room 2123
A2: Pot | B2: # oat | C2: avg length (mm) | D2: avg weight (mg) | E2: tot weight (g) | F2: # tom | G2: avg length (mm) | H2: avg weight (mg) | I2: tot weight (g) | K2: Pot | L2: # oat | M2: avg length (mm) | N2: avg weight (mg) | O2: tot weight (g) | P2: # tom | Q2: avg length (mm) | R2: avg weight (mg) | S2: tot weight (g) | U2: Pot | V2: # oat | W2: avg length (mm) | X2: avg weight (mg) | Y2: tot weight (g) | Z2: # tom | AA2: avg length (mm) | AB2: avg weight (mg) | AC2: tot weight (g) | AE2: Pot | AF2: # oat | AG2: avg length (mm) | AH2: avg weight (mg) | AI2: tot weight (g) | AJ2: # tom | AK2: avg length (mm) | AL2: avg weight (mg) | AM2: tot weight (g)
A3: ------/30 tom | F3: 16 | G3: 32.93 | H3: 34.375 | I3: 0.55 | K3: ------/30 tom | P3: 23 | Q3: 3.5 | R3: 54.78 | S3: 1.26 | U3: ------/30 tom | Z3: 25 | AA3: 51.72 | AB3: 105.2 | AC3: 2.63 | AE3: ------/30 tom | AJ3: 12 | AK3: 43.96 | AL3: 56.67 | AM3: 0.68
A4: 10 oat/20 tom | B4: 10 | C4: 176 | D4: 176 | E4: 1.76 | F4: 7 | G4: 27.3 | H4: 38.6 | I4: 0.27 | K4: 10 oat/20 tom | L4: 9 | M4: 163.33 | N4: 223.33 | O4: 2.01 | P4: 11 | Q4: 27.54 | R4: 30 | S4: 0.33 | U4: 10 oat/20 tom | V4: 9 | W4: 262.4 | X4: 489 | Y4: 4.4 | Z4: 16 | AA4: 48.6 | AB4: 76.3 | AC4: 1.22 | AE4: 10 oat/20 tom | AF4: 9 | AG4: 229.33 | AH4: 386.6 | AI4: 3.48 | AJ4: 14 | AK4: 38.85 | AL4: 50 | AM4: 0.7
A5: 20 oat/10 tom | B5: 18 | C5: 174.6 | D5: 170.55 | E5: 3.07 | F5: 9 | G5: 25.8 | H5: 28.8 | I5: 0.26 | K5: 20 oat/10 tom | L5: 20 | M5: 173.9 | N5: 214.5 | O5: 4.29 | P5: 6 | Q5: 35.33 | R5: 38.33 | S5: 0.23 | U5: 20 oat/10 tom | V5: 20 | W5: 255.5 | X5: 451.5 | Y5: 9.03 | Z5: 5 | AA5: 49.2 | AB5: 68 | AC5: 0.34 | AE5: 20 oat/10 tom | AF5: 19 | AG5: 229.59 | AH5: 375.26 | AI5: 7.13 | AJ5: 2 | AK5: 37 | AL5: 40 | AM5: 0.08
A6: 30 oat/------ | B6: 28 | C6: 171.161 | D6: 177.857 | E6: 4.98 | K6: 30 oat/------ | L6: 29 | M6: 162.79 | N6: 185.17 | O6: 5.37 | U6: 30 oat/------ | V6: 28 | W6: 243.36 | X6: 392 | Y6: 10.98 | AE6: 30 oat/------ | AF6: 29 | AG6: 253.24 | AH6: 412 | AI6: 11.95
A8: Pot | B8: # oat | C8: avg length (mm) | D8: avg weight (mg) | E8: tot weight (g) | F8: # alf | G8: avg length (mm) | H8: avg weight (mg) | I8: tot weight (g) | K8: Pot | L8: # oat | M8: avg length (mm) | N8: avg weight (mg) | O8: tot weight (g) | P8: # alf | Q8: avg length (mm) | R8: avg weight (mg) | S8: tot weight (g) | U8: Pot | V8: # oat | W8: avg length (mm) | X8: avg weight (mg) | Y8: tot weight (g) | Z8: # alf | AA8: avg length (mm) | AB8: avg weight (mg) | AC8: tot weight (g) | AE8: Pot | AF8: # oat | AG8: avg length (mm) | AH8: avg weight (mg) | AI8: tot weight (g) | AJ8: # alf | AK8: avg length (mm) | AL8: avg weight (mg) | AM8: tot weight (g)
A9: ------/30 alf | F9: 16 | G9: 52.065 | H9: 133.125 | I9: 2.13 | K9: ------/30 alf | P9: 17 | Q9: 61.11 | R9: 146.47 | S9: 2.49 | U9: ------/30 alf | Z9: 20 | AA9: 69.65 | AB9: 113.5 | AC9: 2.27 | AE9: ------/30 alf | AJ9: 19 | AK9: 58.68 | AL9: 114 | AM9: 2.17
A10: 10 oat/20 alf | B10: 10 | C10: 158.9 | D10: 169 | E10: 1.69 | F10: 3 | G10: 41.33 | H10: 173.33 | I10: 0.52 | K10: 10 oat/20 alf | L10: 9 | M10: 158.33 | N10: 183.33 | O10: 1.65 | P10: 20 | Q10: 51.8 | R10: 135.5 | S10: 2.71 | U10: 10 oat/20 alf | V10: 10 | W10: 252.9 | X10: 486.25 | Y10: 4.86 | Z10: 11 | AA10: 59.27 | AB10: 110.2 | AC10: 1.21 | AE10: 10 oat/20 alf | AF10: 10 | AG10: 214.1 | AH10: 449 | AI10: 4.49 | AJ10: 8 | AK10: 54.875 | AL10: 115 | AM10: 0.92
A11: 20 oat/10 alf | B11: 19 | C11: 152.211 | D11: 208.947 | E11: 3.97 | F11: 3 | G11: 18 | H11: 13.3 | I11: 0.04 | K11: 20 oat/10 alf | L11: 19 | M11: 141.1 | N11: 151.57 | O11: 2.88 | P11: 9 | Q11: 54.55 | R11: 144.44 | S11: 1.3 | U11: 20 oat/10 alf | V11: 20 | W11: 230.75 | X11: 429 | Y11: 8.58 | Z11: 6 | AA11: 51.5 | AB11: 91.67 | AC11: 0.55 | AE11: 20 oat/10 alf | AF11: 20 | AG11: 239.1 | AH11: 355.5 | AI11: 7.11 | AJ11: 3 | AK11: 50.34 | AL11: 123.34 | AM11: 0.37
A12: 30 oat/------ | B12: 28 | C12: 171.161 | D12: 177.857 | E12: 4.98 | K12: 30 oat/------ | L12: 29 | M12: 162.79 | N12: 185.17 | O12: 5.37 | U12: 30 oat/------ | V12: 28 | W12: 243.36 | X12: 392.14 | Y12: 10.98 | AE12: 30 oat/------ | AF12: 29 | AG12: 253.24 | AH12: 412 | AI12: 11.95
A14: Pot | B14: # tom | C14: avg length (mm) | D14: avg weight (mg) | E14: tot weight (g) | F14: # alf | G14: avg length (mm) | H14: avg weight (mg) | I14: tot weight (g) | K14: Pot | L14: # tom | M14: avg length (mm) | N14: avg weight (mg) | O14: tot weight (g) | P14: # alf | Q14: avg length (mm) | R14: avg weight (mg) | S14: tot weight (g) | U14: Pot | V14: # tom | W14: avg length (mm) | X14: avg weight (mg) | Y14: tot weight (g) | Z14: # alf | AA14: avg length (mm) | AB14: avg weight (mg) | AC14: tot weight (g) | AE14: Pot | AF14: # tom | AG14: avg length (mm) | AH14: avg weight (mg) | AI14: tot weight (g) | AJ14: # alf | AK14: avg length (mm) | AL14: avg weight (mg) | AM14: tot weight (g)
A15: ------ /30 alf | F15: 16 | G15: 52.065 | H15: 133.125 | I15: 2.13 | K15: ------ /30 alf | P15: 17 | Q15: 61.11 | R15: 146.47 | S15: 2.49 | U15: ------ /30 alf | Z15: 20 | AA15: 69.65 | AB15: 113.5 | AC15: 2.27 | AE15: ------ /30 alf | AJ15: 19 | AK15: 58.68 | AL15: 516.84 | AM15: 9.82
A16: 10 tom /20 alf | B16: 7 | C16: 31.86 | D16: 47.14 | E16: 0.33 | F16: 14 | G16: 58.71 | H16: 146.43 | I16: 2.05 | K16: 10 tom /20 alf | L16: 5 | M16: 3.5 | N16: 34 | O16: 0.17 | P16: 16 | Q16: 5.66 | R16: 131.87 | S16: 2.11 | U16: 10 tom /20 alf | V16: 7 | W16: 60 | X16: 158.57 | Y16: 1.11 | Z16: 12 | AA16: 79.92 | AB16: 196.67 | AC16: 2.36 | AE16: 10 tom /20 alf | AF16: 9 | AG16: 44.277 | AH16: 43.33 | AI16: 0.39 | AJ16: 11 | AK16: 68 | AL16: 176.36 | AM16: 1.94
A17: 20 tom /10 alf | B17: 11 | C17: 26.545 | D17: 32.5 | E17: 0.3575 | F17: 5 | G17: 68 | H17: 186.14 | I17: 0.9307 | K17: 20 tom /10 alf | L17: 11 | M17: 29.27 | N17: 31.81 | O17: 0.35 | P17: 7 | Q17: 57 | R17: 185.71 | S17: 1.3 | U17: 20 tom /10 alf | V17: 14 | W17: 54 | X17: 66.43 | Y17: 0.93 | Z17: 10 | AA17: 88.3 | AB17: 211 | AC17: 2.11 | AE17: 20 tom /10 alf | AF17: 13 | AG17: 35.42 | AH17: 50.77 | AI17: 0.66 | AJ17: 8 | AK17: 72.75 | AL17: 206.25 | AM17: 1.65
A18: 30 tom /------ | B18: 16 | C18: 32.93 | D18: 34.375 | E18: 0.55 | K18: 30 tom /------ | L18: 23 | M18: 3.5 | N18: 54.78 | O18: 1.26 | U18: 30 tom /------ | V18: 25 | W18: 51.72 | X18: 105.2 | Y18: 2.63 | AE18: 30 tom /------ | AF18: 12 | AG18: 43.96 | AH18: 56.67 | AI18: 0.68
A20: note- data for each monoculture pot must be entered in two places above

Sheet T7-10
E1: Room 2114 | J1: | | O1: Room 2122 | T1: | | Y1: Room 2115 | AD1: | | AI1: Room 2123
A2: Pot | B2: # oat | C2: avg length (mm) | D2: avg weight (mg) | E2: tot weight (g) | F2: # tom | G2: avg length (mm) | H2: avg weight (mg) | I2: tot weight (g) | K2: Pot | L2: # oat | M2: avg length (mm) | N2: avg weight (mg) | O2: tot weight (g) | P2: # tom | Q2: avg length (mm) | R2: avg weight (mg) | S2: tot weight (g) | U2: Pot | V2: # oat | W2: avg length (mm) | X2: avg weight (mg) | Y2: tot weight (g) | Z2: # tom | AA2: avg length (mm) | AB2: avg weight (mg) | AC2: tot weight (g) | AE2: Pot | AF2: # oat | AG2: avg length (mm) | AH2: avg weight (mg) | AI2: tot weight (g) | AJ2: # tom | AK2: avg length (mm) | AL2: avg weight (mg) | AM2: tot weight (g)
A3: ------/30 tom | F3: 27 | G3: 37.85 | H3: 38.9 | I3: 1.05 | K3: ------/30 tom | P3: 21 | Q3: 32.86 | R3: 40.95 | S3: 0.86 | U3: ------/30 tom | Z3: 19 | AA3: 51.632 | AB3: 91.579 | AC3: 1.74 | AE3: ------/30 tom | AJ3: 19 | AK3: 37.68 | AL3: 79.47 | AM3: 1.5
A4: 10 oat/20 tom | B4: 9 | C4: 157.6 | D4: 148.9 | E4: 1.34 | F4: 14 | G4: 24.76 | H4: 42.857 | I4: 0.6 | K4: 10 oat/20 tom | L4: 8 | M4: 187.5 | N4: 252.5 | O4: 2.02 | P4: 16 | Q4: 33.81 | R4: 43.13 | S4: 0.69 | U4: 10 oat/20 tom | V4: 18 | W4: 201.67 | X4: 354.444 | Y4: 6.38 | Z4: 14 | AA4: 41.79 | AB4: 47.86 | AC4: 0.67 | AE4: 10 oat/20 tom | AF4: 10 | AG4: 230.5 | AH4: 492 | AI4: 4.92 | AJ4: 19 | AK4: 38.05 | AL4: 50.53 | AM4: 0.96
A5: 20 oat/10 tom | B5: 20 | C5: 165.25 | D5: 145 | E5: 2.9 | F5: 9 | G5: 28.1 | H5: 33.33 | I5: 0.3 | K5: 20 oat/10 tom | L5: 16 | M5: 143.56 | N5: 171.88 | O5: 2.75 | P5: 10 | Q5: 27.9 | R5: 25 | S5: 0.25 | U5: 20 oat/10 tom | V5: 20 | W5: 227.25 | X5: 481 | Y5: 9.62 | Z5: 8 | AA5: 49.125 | AB5: 66.25 | AC5: 0.53 | AE5: 20 oat/10 tom | AF5: 19 | AG5: 224.5 | AH5: 418.4 | AI5: 7.95 | AJ5: 9 | AK5: 49.3 | AL5: 48.9 | AM5: 0.44
A6: 30 oat/------ | B6: 29 | C6: 175.72 | D6: 184.13 | E6: 5.34 | K6: 30 oat/------ | L6: 30 | M6: 148.9 | N6: 162.67 | O6: 4.88 | U6: 30 oat/------ | V6: 30 | W6: 223.2 | X6: 425.33 | Y6: 12.76 | AE6: 30 oat/------ | AF6: 30 | AG6: 269.77 | AH6: 411.33 | AI6: 12.34
A8: Pot | B8: # oat | C8: avg length (mm) | D8: avg weight (mg) | E8: tot weight (g) | F8: # alf | G8: avg length (mm) | H8: avg weight (mg) | I8: tot weight (g) | K8: Pot | L8: # oat | M8: avg length (mm) | N8: avg weight (mg) | O8: tot weight (g) | P8: # alf | Q8: avg length (mm) | R8: avg weight (mg) | S8: tot weight (g) | U8: Pot | V8: # oat | W8: avg length (mm) | X8: avg weight (mg) | Y8: tot weight (g) | Z8: # alf | AA8: avg length (mm) | AB8: avg weight (mg) | AC8: tot weight (g) | AE8: Pot | AF8: # oat | AG8: avg length (mm) | AH8: avg weight (mg) | AI8: tot weight (g) | AJ8: # alf | AK8: avg length (mm) | AL8: avg weight (mg) | AM8: tot weight (g)
A9: ------/30 alf | F9: 16 | G9: 65 | H9: 181.25 | I9: 2.9 | K9: ------/30 alf | P9: 20 | Q9: 3.59 | R9: 105 | S9: 2.1 | U9: ------/30 alf | Z9: 14 | AA9: 74.75 | AB9: 149.72 | AC9: 2.0961 | AE9: ------/30 alf | AJ9: 21 | AK9: 60.66 | AL9: 135.7 | AM9: 2.85
A10: 10 oat/20 alf | B10: na | C10: na | D10: na | E10: na | F10: na | G10: na | H10: na | I10: na | K10: 10 oat/20 alf | L10: 10 | M10: 152.1 | N10: 162 | O10: 1.62 | P10: 14 | Q10: 66.64 | R10: 152.14 | S10: 2.13 | U10: 10 oat/20 alf | V10: 10 | W10: 233.2 | X10: 502 | Y10: 5.02 | Z10: 5 | AA10: 44.4 | AB10: 74.2 | AC10: 0.371 | AE10: 10 oat/20 alf | AF10: 9 | AG10: 250.8 | AH10: 576.6 | AI10: 5.19 | AJ10: 11 | AK10: 50.27 | AL10: 131.8 | AM10: 1.45
A11: 20 oat/10 alf | B11: 20 | C11: 187.55 | D11: 168.485 | E11: 3.3687 | F11: 3 | G11: 56 | H11: 124.6 | I11: 0.3738 | K11: 20 oat/10 alf | L11: 18 | M11: 169.78 | N11: 162.22 | O11: 2.92 | P11: 9 | Q11: 67.11 | R11: 187.78 | S11: 1.69 | U11: 20 oat/10 alf | V11: 20 | W11: 227.05 | X11: 345.5 | Y11: 6.91 | Z11: 8 | AA11: 38 | AB11: 60.26 | AC11: 0.482 | AE11: 20 oat/10 alf | AF11: 20 | AG11: 224.8 | AH11: 373 | AI11: 7.46 | AJ11: 9 | AK11: 49.11 | AL11: 83.33 | AM11: 0.75
A12: 30 oat/------ | B12: 29 | C12: 175.72 | D12: 184.13 | E12: 5.34 | K12: 30 oat/------ | L12: 30 | M12: 148.9 | N12: 162.67 | O12: 4.88 | U12: 30 oat/------ | V12: 30 | W12: 223.2 | X12: 425.33 | Y12: 12.76 | AE12: 30 oat/------ | AF12: 30 | AG12: 269.77 | AH12: 411.33 | AI12: 12.34
A14: Pot | B14: # tom | C14: avg length (mm) | D14: avg weight (mg) | E14: tot weight (g) | F14: # alf | G14: avg length (mm) | H14: avg weight (mg) | I14: tot weight (g) | K14: Pot | L14: # tom | M14: avg length (mm) | N14: avg weight (mg) | O14: tot weight (g) | P14: # alf | Q14: avg length (mm) | R14: avg weight (mg) | S14: tot weight (g) | U14: Pot | V14: # tom | W14: avg length (mm) | X14: avg weight (mg) | Y14: tot weight (g) | Z14: # alf | AA14: avg length (mm) | AB14: avg weight (mg) | AC14: tot weight (g) | AE14: Pot | AF14: # tom | AG14: avg length (mm) | AH14: avg weight (mg) | AI14: tot weight (g) | AJ14: # alf | AK14: avg length (mm) | AL14: avg weight (mg) | AM14: tot weight (g)
A15: ------ /30 alf | F15: 16 | G15: 65 | H15: 181.25 | I15: 2.9 | K15: ------ /30 alf | P15: 20 | Q15: 3.59 | R15: 105 | S15: 2.1 | U15: ------ /30 alf | V15: 0 | Z15: 14 | AA15: 74.75 | AB15: 149.72 | AC15: 2.0961 | AE15: ------ /30 alf | AJ15: 21 | AK15: 60.66 | AL15: 135.7 | AM15: 2.85
A16: 10 tom /20 alf | B16: 4 | C16: 33 | D16: 42.5 | E16: 0.17 | F16: 13 | G16: 51.77 | H16: 113.1 | I16: 1.47 | K16: 10 tom /20 alf | L16: 7 | M16: 39.14 | N16: 52.86 | O16: 0.37 | P16: 16 | Q16: 60.88 | R16: 173.75 | S16: 2.78 | U16: 10 tom /20 alf | V16: 4 | W16: 45 | X16: 82.5 | Y16: 0.33 | Z16: 9 | AA16: 71.44 | AB16: 195.22 | AC16: 1.757 | AE16: 10 tom /20 alf | AF16: 10 | AG16: 50.6 | AH16: 80 | AI16: 0.8 | AJ16: 16 | AK16: 60.44 | AL16: 201.25 | AM16: 3.22
A17: 20 tom /10 alf | B17: 13 | C17: 31 | D17: 30.7 | E17: 0.4 | F17: 3 | G17: 102 | H17: 530 | I17: 1.59 | K17: 20 tom /10 alf | L17: 13 | M17: 32.75 | N17: 38.46 | O17: 0.5 | P17: 8 | Q17: 79.06 | R17: 236.25 | S17: 1.89 | U17: 20 tom /10 alf | V17: 14 | W17: 37.1 | X17: 53.6 | Y17: 0.75 | Z17: 6 | AA17: 66.8 | AB17: 218.6 | AC17: 1.3 | AE17: 20 tom /10 alf | AF17: 13 | AG17: 54.9 | AH17: 89.23 | AI17: 1.16 | AJ17: 8 | AK17: 78.4 | AL17: 306.3 | AM17: 2.45
A18: 30 tom /------ | B18: 27 | C18: 37.85 | D18: 38.9 | E18: 1.05 | K18: 30 tom /------ | L18: 21 | M18: 32.86 | N18: 40.95 | O18: 0.86 | U18: 30 tom /------ | V18: 19 | W18: 51.632 | X18: 91.579 | Y18: 1.74 | AE18: 30 tom /------ | AF18: 19 | AG18: 37.68 | AH18: 79.47 | AI18: 1.5
A20: note- data for each monoculture pot must be entered in two places above

Sheet W9-12
E1: Room 2114 | J1: | | O1: Room 2122 | T1: | | Y1: Room 2115 | AD1: | | AI1: Room 2123
A2: Pot | B2: # oat | C2: avg length (mm) | D2: avg weight (mg) | E2: tot weight (g) | F2: # tom | G2: avg length (mm) | H2: avg weight (mg) | I2: tot weight (g) | K2: Pot | L2: # oat | M2: avg length (mm) | N2: avg weight (mg) | O2: tot weight (g) | P2: # tom | Q2: avg length (mm) | R2: avg weight (mg) | S2: tot weight (g) | U2: Pot | V2: # oat | W2: avg length (mm) | X2: avg weight (mg) | Y2: tot weight (g) | Z2: # tom | AA2: avg length (mm) | AB2: avg weight (mg) | AC2: tot weight (g) | AE2: Pot | AF2: # oat | AG2: avg length (mm) | AH2: avg weight (mg) | AI2: tot weight (g) | AJ2: # tom | AK2: avg length (mm) | AL2: avg weight (mg) | AM2: tot weight (g)
A3: ------/30 tom | F3: na | G3: na | H3: na | I3: na | K3: ------/30 tom | P3: na | Q3: na | R3: na | S3: na | U3: ------/30 tom | Z3: 26 | AA3: 53 | AB3: 125 | AC3: 3.24 | AE3: ------/30 tom | AJ3: 26 | AK3: 43.38461 | AL3: 76.153 | AM3: 1.98
A4: 10 oat/20 tom | B4: na | C4: na | D4: na | E4: na | F4: na | G4: na | H4: na | I4: na | K4: 10 oat/20 tom | L4: 10 | M4: 188.5 | N4: 271 | O4: 2.71 | P4: 13 | Q4: 33.769 | R4: 39.23 | S4: 0.51 | U4: 10 oat/20 tom | V4: 10 | W4: 289 | X4: 628 | Y4: 6.28 | Z4: 15 | AA4: 48 | AB4: 77 | AC4: 1.15 | AE4: 10 oat/20 tom | AF4: 10 | AG4: 257 | AH4: 582 | AI4: 5.82 | AJ4: 13 | AK4: 42.0769 | AL4: 47.6923 | AM4: 0.62
A5: 20 oat/10 tom | B5: na | C5: na | D5: na | E5: na | F5: na | G5: na | H5: na | I5: na | K5: 20 oat/10 tom | L5: 19 | M5: 161.84 | N5: 183.68 | O5: 3.49 | P5: 4 | Q5: 30 | R5: 57.5 | S5: 0.23 | U5: 20 oat/10 tom | V5: 20 | W5: 239 | X5: 329 | Y5: 6.57 | Z5: 7 | AA5: 38 | AB5: 29 | AC5: 0.2 | AE5: 20 oat/10 tom | AF5: 20 | AG5: 202.25 | AH5: 384 | AI5: 7.68 | AJ5: 9 | AK5: 42.2222 | AL5: 55.5555 | AM5: 0.5
A6: 30 oat/------ | B6: na | C6: na | D6: na | E6: na | K6: 30 oat/------ | L6: 25 | M6: 154.48 | N6: 182 | O6: 4.55 | U6: 30 oat/------ | V6: 30 | W6: 249 | X6: 276 | Y6: 8.27 | AE6: 30 oat/------ | AF6: 27 | AG6: 200.22 | AH6: 361.851 | AI6: 9.77
A8: Pot | B8: # oat | C8: avg length (mm) | D8: avg weight (mg) | E8: tot weight (g) | F8: # alf | G8: avg length (mm) | H8: avg weight (mg) | I8: tot weight (g) | K8: Pot | L8: # oat | M8: avg length (mm) | N8: avg weight (mg) | O8: tot weight (g) | P8: # alf | Q8: avg length (mm) | R8: avg weight (mg) | S8: tot weight (g) | U8: Pot | V8: # oat | W8: avg length (mm) | X8: avg weight (mg) | Y8: tot weight (g) | Z8: # alf | AA8: avg length (mm) | AB8: avg weight (mg) | AC8: tot weight (g) | AE8: Pot | AF8: # oat | AG8: avg length (mm) | AH8: avg weight (mg) | AI8: tot weight (g) | AJ8: # alf | AK8: avg length (mm) | AL8: avg weight (mg) | AM8: tot weight (g)
A9: ------/30 alf | F9: na | G9: na | H9: na | I9: na | K9: ------/30 alf | P9: 20 | Q9: 66.725 | R9: 154.5 | S9: 3.09 | U9: ------/30 alf | Z9: 21 | AA9: 59.43 | AB9: 126.19 | AC9: 2.65 | AE9: ------/30 alf | AJ9: 18 | AK9: 64.44 | AL9: 121.67 | AM9: 2.19
A10: 10 oat/20 alf | B10: na | C10: na | D10: na | E10: na | F10: na | G10: na | H10: na | I10: na | K10: 10 oat/20 alf | L10: 10 | M10: 180.5 | N10: 240 | O10: 2.4 | P10: 14 | Q10: 46.57 | R10: 112.857 | S10: 1.58 | U10: 10 oat/20 alf | V10: 10 | W10: 231 | X10: 374 | Y10: 3.74 | Z10: 17 | AA10: 41 | AB10: 82 | AC10: 1.39 | AE10: 10 oat/20 alf | AF10: na | AG10: na | AH10: na | AI10: na | AJ10: na | AK10: na | AL10: na | AM10: na
A11: 20 oat/10 alf | B11: na | C11: na | D11: na | E11: na | F11: na | G11: na | H11: na | I11: na | K11: 20 oat/10 alf | L11: 19 | M11: 164.5 | N11: 389.47 | O11: 7.4 | P11: 5 | Q11: 76.7 | R11: 190 | S11: 0.95 | U11: 20 oat/10 alf | V11: 19 | W11: 238 | X11: 278.9 | Y11: 5.3 | Z11: 8 | AA11: 67.38 | AB11: 133.75 | AC11: 1.07 | AE11: 20 oat/10 alf | AF11: 16 | AG11: 231.4375 | AH11: 445.625 | AI11: 7.13 | AJ11: 10 | AK11: 34.1 | AL11: 62 | AM11: 0.62
A12: 30 oat/------ | B12: na | C12: na | D12: na | E12: na | K12: 30 oat/------ | L12: 25 | M12: 154.48 | N12: 182 | O12: 4.55 | U12: 30 oat/------ | V12: 30 | W12: 249 | X12: 276 | Y12: 8.27 | AE12: 30 oat/------ | AF12: 27 | AG12: 200.22 | AH12: 361.851 | AI12: 9.77
A14: Pot | B14: # tom | C14: avg length (mm) | D14: avg weight (mg) | E14: tot weight (g) | F14: # alf | G14: avg length (mm) | H14: avg weight (mg) | I14: tot weight (g) | K14: Pot | L14: # tom | M14: avg length (mm) | N14: avg weight (mg) | O14: tot weight (g) | P14: # alf | Q14: avg length (mm) | R14: avg weight (mg) | S14: tot weight (g) | U14: Pot | V14: # tom | W14: avg length (mm) | X14: avg weight (mg) | Y14: tot weight (g) | Z14: # alf | AA14: avg length (mm) | AB14: avg weight (mg) | AC14: tot weight (g) | AE14: Pot | AF14: # tom | AG14: avg length (mm) | AH14: avg weight (mg) | AI14: tot weight (g) | AJ14: # alf | AK14: avg length (mm) | AL14: avg weight (mg) | AM14: tot weight (g)
A15: ------ /30 alf | F15: na | G15: na | H15: na | I15: na | K15: ------ /30 alf | P15: 20 | Q15: 66.725 | R15: 154.5 | S15: 3.09 | U15: ------ /30 alf | Z15: 21 | AA15: 59.43 | AB15: 126.19 | AC15: 2.65 | AE15: ------ /30 alf | AJ15: 18 | AK15: 64.44 | AL15: 121.67 | AM15: 2.19
A16: 10 tom /20 alf | B16: na | C16: na | D16: na | E16: na | F16: na | G16: na | H16: na | I16: na | K16: 10 tom /20 alf | L16: 7 | M16: 39.6 | N16: 14 | O16: 0.1 | P16: 17 | Q16: 48.5 | R16: 55 | S16: 0.93 | U16: 10 tom /20 alf | V16: 8 | W16: 46.25 | X16: 71.25 | Y16: 0.57 | Z16: 13 | AA16: 59.2 | AB16: 103.8 | AC16: 1.35 | AE16: 10 tom /20 alf | AF16: 7 | AG16: 41.857142 | AH16: 71.428571 | AI16: 0.5 | AJ16: 16 | AK16: 64.5 | AL16: 217.5 | AM16: 3.48
A17: 20 tom /10 alf | B17: na | C17: na | D17: na | E17: na | F17: na | G17: na | H17: na | I17: na | K17: 20 tom /10 alf | L17: 8 | M17: 42.25 | N17: 57.5 | O17: 0.46 | P17: 10 | Q17: 41.7 | R17: 45 | S17: 0.45 | U17: 20 tom /10 alf | V17: 18 | W17: 60 | X17: 161 | Y17: 2.9 | Z17: 5 | AA17: 53.2 | AB17: 126 | AC17: 0.63 | AE17: 20 tom /10 alf | AF17: 14 | AG17: 48.7857 | AH17: 86.42857 | AI17: 1.21 | AJ17: 10 | AK17: 76.9 | AL17: 232 | AM17: 2.32
A18: 30 tom /------ | B18: na | C18: na | D18: na | E18: na | K18: 30 tom /------ | L18: na | M18: na | N18: na | O18: na | U18: 30 tom /------ | V18: 26 | W18: 53 | X18: 125 | Y18: 3.24 | AE18: 30 tom /------ | AF18: 26 | AG18: 43.38461 | AH18: 76.153 | AI18: 1.98
A20: note- data for each monoculture pot must be entered in two places above

Sheet W2-5
E1: Room 2114 | J1: | | O1: Room 2122 | T1: | | Y1: Room 2115 | AD1: | | AI1: Room 2123
A2: Pot | B2: # oat | C2: avg length (mm) | D2: avg weight (mg) | E2: tot weight (g) | F2: # tom | G2: avg length (mm) | H2: avg weight (mg) | I2: tot weight (g) | K2: Pot | L2: # oat | M2: avg length (mm) | N2: avg weight (mg) | O2: tot weight (g) | P2: # tom | Q2: avg length (mm) | R2: avg weight (mg) | S2: tot weight (g) | U2: Pot | V2: # oat | W2: avg length (mm) | X2: avg weight (mg) | Y2: tot weight (g) | Z2: # tom | AA2: avg length (mm) | AB2: avg weight (mg) | AC2: tot weight (g) | AE2: Pot | AF2: # oat | AG2: avg length (mm) | AH2: avg weight (mg) | AI2: tot weight (g) | AJ2: # tom | AK2: avg length (mm) | AL2: avg weight (mg) | AM2: tot weight (g)
A3: ------/30 tom | F3: na | G3: na | H3: na | I3: na | K3: ------/30 tom | P3: 17 | Q3: 33.35 | R3: 40 | S3: 0.68 | U3: ------/30 tom | Z3: 25 | AA3: 40.8 | AB3: 57.6 | AC3: 1.44 | AE3: ------/30 tom | AJ3: 17 | AK3: 40.18 | AL3: 75.88 | AM3: 1.29
A4: 10 oat/20 tom | B4: na | C4: na | D4: na | E4: na | F4: na | G4: na | H4: na | I4: na | K4: 10 oat/20 tom | L4: 10 | M4: 133.5 | N4: 180 | O4: 1.8 | P4: 13 | Q4: 37 | R4: 46 | S4: 0.6 | U4: 10 oat/20 tom | V4: 10 | W4: 157 | X4: 227 | Y4: 2.27 | Z4: 17 | AA4: 27.9 | AB4: 31.8 | AC4: 0.54 | AE4: 10 oat/20 tom | AF4: 14 | AG4: 225.071 | AH4: 381.428 | AI4: 5.34 | AJ4: 21 | AK4: 39.5238 | AL4: 40.4672 | AM4: 0.85
A5: 20 oat/10 tom | B5: na | C5: na | D5: na | E5: na | F5: na | G5: na | H5: na | I5: na | K5: 20 oat/10 tom | L5: 20 | M5: 147.6 | N5: 185.5 | O5: 3.71 | P5: 7 | Q5: 37.5 | R5: 34.29 | S5: 0.24 | U5: 20 oat/10 tom | V5: 19 | W5: 145.2 | X5: 184.2 | Y5: 3.5 | Z5: 8 | AA5: 40.1 | AB5: 38.8 | AC5: 0.31 | AE5: 20 oat/10 tom | AF5: 19 | AG5: 262.73 | AH5: 453.68 | AI5: 8.62 | AJ5: 10 | AK5: 51 | AL5: 56 | AM5: 0.56
A6: 30 oat/------ | B6: na | C6: na | D6: na | E6: na | K6: 30 oat/------ | L6: 30 | M6: 162 | N6: 163.33 | O6: 4.9 | U6: 30 oat/------ | V6: 29 | W6: 151.93 | X6: 167.93 | Y6: 4.78 | AE6: 30 oat/------ | AF6: 30 | AG6: 260.63 | AH6: 353.33 | AI6: 10.6
A8: Pot | B8: # oat | C8: avg length (mm) | D8: avg weight (mg) | E8: tot weight (g) | F8: # alf | G8: avg length (mm) | H8: avg weight (mg) | I8: tot weight (g) | K8: Pot | L8: # oat | M8: avg length (mm) | N8: avg weight (mg) | O8: tot weight (g) | P8: # alf | Q8: avg length (mm) | R8: avg weight (mg) | S8: tot weight (g) | U8: Pot | V8: # oat | W8: avg length (mm) | X8: avg weight (mg) | Y8: tot weight (g) | Z8: # alf | AA8: avg length (mm) | AB8: avg weight (mg) | AC8: tot weight (g) | AE8: Pot | AF8: # oat | AG8: avg length (mm) | AH8: avg weight (mg) | AI8: tot weight (g) | AJ8: # alf | AK8: avg length (mm) | AL8: avg weight (mg) | AM8: tot weight (g)
A9: ------/30 alf | F9: na | G9: na | H9: na | I9: na | K9: ------/30 alf | P9: 22 | Q9: 52.4 | R9: 82.3 | S9: 1.81 | U9: ------/30 alf | Z9: 26 | AA9: 54 | AB9: 80.769 | AC9: 2.1 | AE9: ------/30 alf | AJ9: 16 | AK9: 51.375 | AL9: 146.875 | AM9: 2.35
A10: 10 oat/20 alf | B10: na | C10: na | D10: na | E10: na | F10: na | G10: na | H10: na | I10: na | K10: 10 oat/20 alf | L10: 10 | M10: 153.6 | N10: 157 | O10: 1.57 | P10: 12 | Q10: 38.25 | R10: 102.5 | S10: 1.23 | U10: 10 oat/20 alf | V10: 10 | W10: 153.1 | X10: 114 | Y10: 1.14 | Z10: 13 | AA10: 70.07 | AB10: 90 | AC10: 1.17 | AE10: 10 oat/20 alf | AF10: 10 | AG10: 264.4 | AH10: 497 | AI10: 4.97 | AJ10: 20 | AK10: 36.55 | AL10: 61.5 | AM10: 1.23
A11: 20 oat/10 alf | B11: na | C11: na | D11: na | E11: na | F11: na | G11: na | H11: na | I11: na | K11: 20 oat/10 alf | L11: 18 | M11: 146.72 | N11: 160.55 | O11: 2.89 | P11: 10 | Q11: 50.93 | R11: 78 | S11: 0.78 | U11: 20 oat/10 alf | V11: 20 | W11: 154.82 | X11: 104 | Y11: 2.08 | Z11: 10 | AA11: 48.4 | AB11: 46 | AC11: 0.46 | AE11: 20 oat/10 alf | AF11: 20 | AG11: 269.55 | AH11: 429 | AI11: 8.58 | AJ11: 11 | AK11: 56.09 | AL11: 60.9 | AM11: 0.67
A12: 30 oat/------ | B12: na | C12: na | D12: na | E12: na | K12: 30 oat/------ | L12: 30 | M12: 162 | N12: 163.33 | O12: 4.9 | U12: 30 oat/------ | V12: 29 | W12: 151.93 | X12: 164.8 | Y12: 4.78 | AE12: 30 oat/------ | AF12: 30 | AG12: 260.63 | AH12: 353.33 | AI12: 10.6
A14: Pot | B14: # tom | C14: avg length (mm) | D14: avg weight (mg) | E14: tot weight (g) | F14: # alf | G14: avg length (mm) | H14: avg weight (mg) | I14: tot weight (g) | K14: Pot | L14: # tom | M14: avg length (mm) | N14: avg weight (mg) | O14: tot weight (g) | P14: # alf | Q14: avg length (mm) | R14: avg weight (mg) | S14: tot weight (g) | U14: Pot | V14: # tom | W14: avg length (mm) | X14: avg weight (mg) | Y14: tot weight (g) | Z14: # alf | AA14: avg length (mm) | AB14: avg weight (mg) | AC14: tot weight (g) | AE14: Pot | AF14: # tom | AG14: avg length (mm) | AH14: avg weight (mg) | AI14: tot weight (g) | AJ14: # alf | AK14: avg length (mm) | AL14: avg weight (mg) | AM14: tot weight (g)
A15: ------ /30 alf | F15: na | G15: na | H15: na | I15: na | K15: ------ /30 alf | P15: 22 | Q15: 52.4 | R15: 82.3 | S15: 1.81 | U15: ------ /30 alf | Z15: 26 | AA15: 54 | AB15: 80.769 | AC15: 2.1 | AE15: ------ /30 alf | AJ15: 16 | AK15: 51.375 | AL15: 146.875 | AM15: 2.35
A16: 10 tom /20 alf | B16: na | C16: na | D16: na | E16: na | F16: na | G16: na | H16: na | I16: na | K16: 10 tom /20 alf | L16: na | M16: na | N16: na | O16: na | P16: 14 | Q16: 68 | R16: 85.7 | S16: 1.2 | U16: 10 tom /20 alf | V16: 7 | W16: 34 | X16: 21.43 | Y16: 0.15 | Z16: 14 | AA16: 74.5 | AB16: 118.57 | AC16: 1.66 | AE16: 10 tom /20 alf | AF16: 7 | AG16: 49.57 | AH16: 82.85 | AI16: 0.58 | AJ16: 17 | AK16: 53.12 | AL16: 103.52 | AM16: 1.76
A17: 20 tom /10 alf | B17: na | C17: na | D17: na | E17: na | F17: na | G17: na | H17: na | I17: na | K17: 20 tom /10 alf | L17: 8 | M17: 69.25 | N17: 126.25 | O17: 1.01 | P17: 7 | Q17: 35 | R17: 24.3 | S17: 0.17 | U17: 20 tom /10 alf | V17: 16 | W17: 36.75 | X17: 31.25 | Y17: 0.5 | Z17: 8 | AA17: 63 | AB17: 160 | AC17: 1.28 | AE17: 20 tom /10 alf | AF17: 16 | AG17: 32.875 | AH17: 80.625 | AI17: 1.29 | AJ17: 8 | AK17: 33.375 | AL17: 127.5 | AM17: 1.02
A18: 30 tom /------ | B18: na | C18: na | D18: na | E18: na | K18: 30 tom /------ | L18: 17 | M18: 33.35 | N18: 40 | O18: 0.68 | U18: 30 tom /------ | V18: 25 | W18: 40.8 | X18: 57.6 | Y18: 1.44 | AE18: 30 tom /------ | AF18: 17 | AG18: 40.18 | AH18: 75.88 | AI18: 1.29
A20: note- data for each monoculture pot must be entered in two places above

Sheet W7-10
E1: Room 2114 | J1: | | O1: Room 2122 | T1: | | Y1: Room 2115 | AD1: | | AI1: Room 2123
A2: Pot | B2: # oat | C2: avg length (mm) | D2: avg weight (mg) | E2: tot weight (g) | F2: # tom | G2: avg length (mm) | H2: avg weight (mg) | I2: tot weight (g) | K2: Pot | L2: # oat | M2: avg length (mm) | N2: avg weight (mg) | O2: tot weight (g) | P2: # tom | Q2: avg length (mm) | R2: avg weight (mg) | S2: tot weight (g) | U2: Pot | V2: # oat | W2: avg length (mm) | X2: avg weight (mg) | Y2: tot weight (g) | Z2: # tom | AA2: avg length (mm) | AB2: avg weight (mg) | AC2: tot weight (g) | AE2: Pot | AF2: # oat | AG2: avg length (mm) | AH2: avg weight (mg) | AI2: tot weight (g) | AJ2: # tom | AK2: avg length (mm) | AL2: avg weight (mg) | AM2: tot weight (g)
A3: ------/30 tom | F3: 35 | G3: 36.03 | H3: 45.14 | I3: 1.58 | K3: ------/30 tom | P3: 23 | Q3: 38.52 | R3: 54.78 | S3: 1.26 | U3: ------/30 tom | Z3: 25 | AA3: 36.32 | AB3: =(AC3*1000)/Z3 -> 66.8 | AC3: 1.67 | AE3: ------/30 tom | AJ3: 25 | AK3: 70.4 | AL3: 66 | AM3: 1.65
A4: 10 oat/20 tom | B4: 10 | C4: 180.7 | D4: =E4*1000/B4 -> 220 | E4: 2.2 | F4: 12 | G4: 36 | H4: 42.5 | I4: 0.51 | K4: 10 oat/20 tom | L4: 9 | M4: 179.33 | N4: 255.56 | O4: 2.3 | P4: 15 | Q4: 42.73 | R4: 37.33 | S4: 0.56 | U4: 10 oat/20 tom | V4: 10 | W4: 259 | X4: =(Y4*1000)/V4 -> 678 | Y4: 6.78 | Z4: 17 | AA4: 44.17 | AB4: =(AC4*1000)/Z4 -> 70.588235 | AC4: 1.2 | AE4: 10 oat/20 tom | AF4: 10 | AG4: 247.9 | AH4: 591 | AI4: 5.91 | AJ4: 20 | AK4: 47.65 | AL4: 64.5 | AM4: 1.29
A5: 20 oat/10 tom | B5: 30 | C5: 162.83 | D5: 120.67 | E5: 3.62 | F5: 7 | G5: 28.86 | H5: 44.29 | I5: 0.31 | K5: 20 oat/10 tom | L5: 20 | M5: 169.2 | N5: 193.5 | O5: 3.87 | P5: 6 | Q5: 39.67 | R5: 57.83 | S5: 0.3469 | U5: 20 oat/10 tom | V5: 20 | W5: 225.5 | X5: =(Y5*1000)/V5 -> 394.5 | Y5: 7.89 | Z5: 6 | AA5: 39.5 | AB5: =(AC5*1000)/Z5 -> 40 | AC5: 0.24 | AE5: 20 oat/10 tom | AF5: 32 | AG5: 339 | AH5: 326 | AI5: 10.45 | AJ5: 13 | AK5: 195.6 | AL5: 42.3 | AM5: 0.55
A6: 30 oat/------ | B6: 30 | C6: 166.03 | D6: 179 | E6: 5.37 | K6: 30 oat/------ | L6: na | M6: na | N6: na | O6: na | U6: 30 oat/------ | V6: 30 | W6: 221.3 | X6: =(Y6*1000)/V6 -> 364.33333 | Y6: 10.93 | AE6: 30 oat/------ | AF6: 30 | AG6: 182.6 | AH6: 407 | AI6: 12.21
A8: Pot | B8: # oat | C8: avg length (mm) | D8: avg weight (mg) | E8: tot weight (g) | F8: # alf | G8: avg length (mm) | H8: avg weight (mg) | I8: tot weight (g) | K8: Pot | L8: # oat | M8: avg length (mm) | N8: avg weight (mg) | O8: tot weight (g) | P8: # alf | Q8: avg length (mm) | R8: avg weight (mg) | S8: tot weight (g) | U8: Pot | V8: # oat | W8: avg length (mm) | X8: avg weight (mg) | Y8: tot weight (g) | Z8: # alf | AA8: avg length (mm) | AB8: avg weight (mg) | AC8: tot weight (g) | AE8: Pot | AF8: # oat | AG8: avg length (mm) | AH8: avg weight (mg) | AI8: tot weight (g) | AJ8: # alf | AK8: avg length (mm) | AL8: avg weight (mg) | AM8: tot weight (g)
A9: ------/30 alf | F9: 21 | G9: 49.48 | H9: 0.143 | I9: 3.01 | K9: ------/30 alf | P9: 20 | Q9: 55.45 | R9: 127 | S9: 2.54 | U9: ------/30 alf | Z9: 7 | AA9: 92 | AB9: =(AC9*1000)/Z9 -> 388.57143 | AC9: 2.72 | AE9: ------/30 alf | AJ9: 17 | AK9: 100.3 | AL9: 101 | AM9: 1.72
A10: 10 oat/20 alf | B10: 10 | C10: 167.5 | D10: 148 | E10: 1.48 | F10: 15 | G10: 35.66 | H10: 106.66 | I10: 1.6 | K10: 10 oat/20 alf | L10: 9 | M10: 159.44 | N10: 224.44 | O10: 2.02 | P10: 15 | Q10: 73.267 | R10: 207.33 | S10: 3.11 | U10: 10 oat/20 alf | V10: 6 | W10: 61.833 | X10: =(Y10*1000)/V10 -> 243.33333 | Y10: 1.46 | Z10: 11 | AA10: 237 | AB10: =(AC10*1000)/Z10 -> 412.72727 | AC10: 4.54 | AE10: 10 oat/20 alf | AF10: 10 | AG10: 239 | AH10: 504 | AI10: 5.04 | AJ10: 9 | AK10: 41.7 | AL10: 91.1417 | AM10: 0.82
A11: 20 oat/10 alf | B11: 18 | C11: 175.5 | D11: 177.7 | E11: 3.2 | F11: 3 | G11: 55 | H11: 143.33 | I11: 0.43 | K11: 20 oat/10 alf | L11: 20 | M11: 169.25 | N11: 213.5 | O11: 4.27 | P11: 6 | Q11: 62.667 | R11: 176.667 | S11: 1.06 | U11: 20 oat/10 alf | V11: 19 | W11: 225 | X11: =(Y11*1000)/V11 -> 290 | Y11: 5.51 | Z11: 4 | AA11: 45 | AB11: =(AC11*1000)/Z11 -> 92.5 | AC11: 0.37 | AE11: 20 oat/10 alf | AF11: 20 | AG11: 463.6 | AH11: 459 | AI11: 9.18 | AJ11: 8 | AK11: 39.375 | AL11: 130 | AM11: 1.04
A12: 30 oat/------ | B12: 30 | C12: 166.03 | D12: 179 | E12: 5.37 | K12: 30 oat/------ | L12: na | M12: na | N12: na | O12: na | U12: 30 oat/------ | V12: 30 | W12: 221.3 | X12: =(Y12*1000)/V12 -> 364.33333 | Y12: 10.93 | AE12: 30 oat/------ | AF12: 30 | AG12: 182.6 | AH12: 407 | AI12: 12.21
A14: Pot | B14: # tom | C14: avg length (mm) | D14: avg weight (mg) | E14: tot weight (g) | F14: # alf | G14: avg length (mm) | H14: avg weight (mg) | I14: tot weight (g) | K14: Pot | L14: # tom | M14: avg length (mm) | N14: avg weight (mg) | O14: tot weight (g) | P14: # alf | Q14: avg length (mm) | R14: avg weight (mg) | S14: tot weight (g) | U14: Pot | V14: # tom | W14: avg length (mm) | X14: avg weight (mg) | Y14: tot weight (g) | Z14: # alf | AA14: avg length (mm) | AB14: avg weight (mg) | AC14: tot weight (g) | AE14: Pot | AF14: # tom | AG14: avg length (mm) | AH14: avg weight (mg) | AI14: tot weight (g) | AJ14: # alf | AK14: avg length (mm) | AL14: avg weight (mg) | AM14: tot weight (g)
A15: ------ /30 alf | F15: 21 | G15: 49.48 | H15: 143.33 | I15: 3.01 | K15: ------ /30 alf | P15: 20 | Q15: 55.45 | R15: 127 | S15: 2.54 | U15: ------ /30 alf | Z15: 7 | AA15: 92 | AB15: =(AC15*1000)/Z15 -> 388.57143 | AC15: 2.72 | AE15: ------ /30 alf | AJ15: 17 | AK15: 100.3 | AL15: 101 | AM15: 1.72
A16: 10 tom /20 alf | B16: 4 | C16: 62.11 | D16: 164.44 | E16: 2.96 | F16: 18 | G16: 29.86 | H16: 42.86 | I16: 0.3 | K16: 10 tom /20 alf | L16: 9 | M16: 41 | N16: 44.44 | O16: 0.4 | P16: 16 | Q16: 74.94 | R16: 185 | S16: 2.96 | U16: 10 tom /20 alf | V16: 9 | W16: 44.44 | X16: =(Y16*1000)/V16 -> 73.333333 | Y16: 0.66 | Z16: 10 | AA16: 93.5 | AB16: =(AC16*1000)/Z16 -> 223 | AC16: 2.23 | AE16: 10 tom /20 alf | AF16: 5 | AG16: 54.4 | AH16: 102 | AI16: 0.51 | AJ16: 12 | AK16: 62.42 | AL16: 165.8 | AM16: 1.99
A17: 20 tom /10 alf | B17: 17 | C17: 37.765 | D17: 40 | E17: 0.68 | F17: 13 | G17: 59.846 | H17: 151.538 | I17: 1.97 | K17: 20 tom /10 alf | L17: 16 | M17: 32.625 | N17: 37.5 | O17: 0.6 | P17: 8 | Q17: 86.5 | R17: 296.25 | S17: 2.37 | U17: 20 tom /10 alf | V17: 14 | W17: 43.64 | X17: =(Y17*1000)/V17 -> 71.428571 | Y17: 1 | Z17: 5 | AA17: 98 | AB17: =(AC17*1000)/Z17 -> 314 | AC17: 1.57 | AE17: 20 tom /10 alf | AF17: na | AG17: na | AH17: na | AI17: na | AJ17: na | AK17: na | AL17: na | AM17: na
A18: 30 tom /------ | B18: 35 | C18: 36.03 | D18: 45.14 | E18: 1.58 | K18: 30 tom /------ | L18: 23 | M18: 38.52 | N18: 54.78 | O18: 1.26 | U18: 30 tom /------ | V18: 25 | W18: 36.32 | X18: =(Y18*1000)/V18 -> 66.8 | Y18: 1.67 | AE18: 30 tom /------ | AF18: 25 | AG18: 70.4 | AH18: 66 | AI18: 1.65
A20: note- data for each monoculture pot must be entered in two places above

Sheet Th9-12
E1: Room 2114 | J1: | | O1: Room 2122 | T1: | | Y1: Room 2115 | AD1: | | AI1: Room 2123
A2: Pot | B2: # oat | C2: avg length (mm) | D2: avg weight (mg) | E2: tot weight (g) | F2: # tom | G2: avg length (mm) | H2: avg weight (mg) | I2: tot weight (g) | K2: Pot | L2: # oat | M2: avg length (mm) | N2: avg weight (mg) | O2: tot weight (g) | P2: # tom | Q2: avg length (mm) | R2: avg weight (mg) | S2: tot weight (g) | U2: Pot | V2: # oat | W2: avg length (mm) | X2: avg weight (mg) | Y2: tot weight (g) | Z2: # tom | AA2: avg length (mm) | AB2: avg weight (mg) | AC2: tot weight (g) | AE2: Pot | AF2: # oat | AG2: avg length (mm) | AH2: avg weight (mg) | AI2: tot weight (g) | AJ2: # tom | AK2: avg length (mm) | AL2: avg weight (mg) | AM2: tot weight (g)
A3: ------/30 tom | F3: 24 | G3: 26.91 | H3: 44.583 | I3: 1.07 | K3: ------/30 tom | P3: 26 | Q3: 30.192 | R3: 51.1538 | S3: 1.33 | U3: ------/30 tom | Z3: 23 | AA3: 44.5 | AB3: 80.4 | AC3: 1.85 | AE3: ------/30 tom | AJ3: 22 | AK3: 42.045454 | AL3: 88.1818 | AM3: 1.94
A4: 10 oat/20 tom | B4: 10 | C4: 155.5 | D4: 163 | E4: 1.63 | F4: 19 | G4: 35.05 | H4: 45.26 | I4: 0.86 | K4: 10 oat/20 tom | L4: 10 | M4: 167.5 | N4: 185 | O4: 1.85 | P4: 15 | Q4: 33.4 | R4: 37.3 | S4: 0.56 | U4: 10 oat/20 tom | V4: 9 | W4: 313.9 | X4: 510 | Y4: 4.59 | Z4: 18 | AA4: 40.7 | AB4: 57.8 | AC4: 1.04 | AE4: 10 oat/20 tom | AF4: 10 | AG4: 234 | AH4: 481 | AI4: 4.81 | AJ4: 15 | AK4: 42.6 | AL4: 60.666667 | AM4: 0.91
A5: 20 oat/10 tom | B5: 19 | C5: 165.579 | D5: 201.05 | E5: 3.82 | F5: 9 | G5: 40.889 | H5: 36.67 | I5: 0.33 | K5: 20 oat/10 tom | L5: 27 | M5: 162.9 | N5: 163.48 | O5: 4.414 | P5: 14 | Q5: 29.5 | R5: 29.28 | S5: 0.41 | U5: 20 oat/10 tom | V5: 20 | W5: 251.5 | X5: 400 | Y5: 8 | Z5: 9 | AA5: 34.6 | AB5: 54.4 | AC5: 0.49 | AE5: 20 oat/10 tom | AF5: 19 | AG5: 261 | AH5: 468.42105 | AI5: 8.9 | AJ5: 9 | AK5: 41.666666 | AL5: 66.66666 | AM5: 0.6
A6: 30 oat/------ | B6: 30 | C6: 130.667 | D6: 196.667 | E6: 5.9 | K6: 30 oat/------ | L6: 30 | M6: 155.16 | N6: 180 | O6: 5.4 | U6: 30 oat/------ | V6: 30 | W6: 263.5 | X6: 298 | Y6: 8.95 | AE6: 30 oat/------ | AF6: 29 | AG6: 268 | AH6: 415.172 | AI6: 12.04
A8: Pot | B8: # oat | C8: avg length (mm) | D8: avg weight (mg) | E8: tot weight (g) | F8: # alf | G8: avg length (mm) | H8: avg weight (mg) | I8: tot weight (g) | K8: Pot | L8: # oat | M8: avg length (mm) | N8: avg weight (mg) | O8: tot weight (g) | P8: # alf | Q8: avg length (mm) | R8: avg weight (mg) | S8: tot weight (g) | U8: Pot | V8: # oat | W8: avg length (mm) | X8: avg weight (mg) | Y8: tot weight (g) | Z8: # alf | AA8: avg length (mm) | AB8: avg weight (mg) | AC8: tot weight (g) | AE8: Pot | AF8: # oat | AG8: avg length (mm) | AH8: avg weight (mg) | AI8: tot weight (g) | AJ8: # alf | AK8: avg length (mm) | AL8: avg weight (mg) | AM8: tot weight (g)
A9: ------/30 alf | F9: 40 | G9: 47.5 | H9: 82.75 | I9: 3.31 | K9: ------/30 alf | P9: 26 | Q9: 41.88 | R9: 121.53 | S9: 3.16 | U9: ------/30 alf | Z9: 24 | AA9: 61.3 | AB9: 92.5 | AC9: 2.22 | AE9: ------/30 alf | AJ9: 26 | AK9: 54.423076 | AL9: 93.076923 | AM9: 2.42
A10: 10 oat/20 alf | B10: 9 | C10: 191.11 | D10: 226.67 | E10: 2.04 | F10: 13 | G10: 58.46 | H10: 174.62 | I10: 2.27 | K10: 10 oat/20 alf | L10: na | M10: na | N10: na | O10: na | P10: na | Q10: na | R10: na | S10: na | U10: 10 oat/20 alf | V10: 10 | W10: 324 | X10: 575 | Y10: 5.75 | Z10: 7 | AA10: 60.7 | AB10: 138.6 | AC10: 0.97 | AE10: 10 oat/20 alf | AF10: 10 | AG10: 216.7 | AH10: 301 | AI10: 3.01 | AJ10: 18 | AK10: 49.611111 | AL10: 60.555556 | AM10: 1.09
A11: 20 oat/10 alf | B11: 18 | C11: 170.22 | D11: 179.444 | E11: 3.23 | F11: 10 | G11: 34.8 | H11: 44 | I11: 0.44 | K11: 20 oat/10 alf | L11: 20 | M11: 165.25 | N11: 173 | O11: 3.46 | P11: 7 | Q11: 65.14 | R11: 218.57 | S11: 1.53 | U11: 20 oat/10 alf | V11: 21 | W11: 264.1 | X11: 416.7 | Y11: 8.75 | Z11: 7 | AA11: 73.4 | AB11: 180 | AC11: 1.26 | AE11: 20 oat/10 alf | AF11: 20 | AG11: 261.2 | AH11: 470.5 | AI11: 9.41 | AJ11: 7 | AK11: 46 | AL11: 92.85 | AM11: 0.65
A12: 30 oat/------ | B12: 30 | C12: 130.667 | D12: 196.667 | E12: 5.9 | K12: 30 oat/------ | L12: 30 | M12: 155.16 | N12: 180 | O12: 5.4 | U12: 30 oat/------ | V12: 30 | W12: 263.5 | X12: 298 | Y12: 8.95 | AE12: 30 oat/------ | AF12: 29 | AG12: 268 | AH12: 415.172 | AI12: 12.04
A14: Pot | B14: # tom | C14: avg length (mm) | D14: avg weight (mg) | E14: tot weight (g) | F14: # alf | G14: avg length (mm) | H14: avg weight (mg) | I14: tot weight (g) | K14: Pot | L14: # tom | M14: avg length (mm) | N14: avg weight (mg) | O14: tot weight (g) | P14: # alf | Q14: avg length (mm) | R14: avg weight (mg) | S14: tot weight (g) | U14: Pot | V14: # tom | W14: avg length (mm) | X14: avg weight (mg) | Y14: tot weight (g) | Z14: # alf | AA14: avg length (mm) | AB14: avg weight (mg) | AC14: tot weight (g) | AE14: Pot | AF14: # tom | AG14: avg length (mm) | AH14: avg weight (mg) | AI14: tot weight (g) | AJ14: # alf | AK14: avg length (mm) | AL14: avg weight (mg) | AM14: tot weight (g)
A15: ------ /30 alf | F15: 40 | G15: 47.5 | H15: 82.75 | I15: 3.31 | K15: ------ /30 alf | P15: 26 | Q15: 41.88 | R15: 121.53 | S15: 3.16 | U15: ------ /30 alf | Z15: 24 | AA15: 61.3 | AB15: 92.5 | AC15: 2.22 | AE15: ------ /30 alf | AJ15: 26 | AK15: 54.423076 | AL15: 93.076923 | AM15: 2.42
A16: 10 tom /20 alf | B16: 7 | C16: 31 | D16: 41.429 | E16: 0.29 | F16: 14 | G16: 57.79 | H16: 234.29 | I16: 3.28 | K16: 10 tom /20 alf | L16: 5 | M16: 27.5 | N16: 36 | O16: 0.18 | P16: 19 | Q16: 47.08 | R16: 125.26 | S16: 2.38 | U16: 10 tom /20 alf | V16: 8 | W16: 56.9 | X16: 40 | Y16: 0.32 | Z16: 11 | AA16: 90.45 | AB16: 135.5 | AC16: 1.49 | AE16: 10 tom /20 alf | AF16: 10 | AG16: 39.9 | AH16: 50 | AI16: 0.5 | AJ16: 14 | AK16: 75.642857 | AL16: 161.42857 | AM16: 2.26
A17: 20 tom /10 alf | B17: 14 | C17: 33.93 | D17: 41.43 | E17: 0.58 | F17: 4 | G17: 73.5 | H17: 172.5 | I17: 0.69 | K17: 20 tom /10 alf | L17: 15 | M17: 36.867 | N17: 35.33 | O17: 0.53 | P17: 6 | Q17: 70 | R17: 146.67 | S17: 0.88 | U17: 20 tom /10 alf | V17: 18 | W17: 44.8 | X17: 85.6 | Y17: 1.54 | Z17: 9 | AA17: 78.1 | AB17: 205.6 | AC17: 1.85 | AE17: 20 tom /10 alf | AF17: 20 | AG17: 44.7 | AH17: 56.5 | AI17: 1.13 | AJ17: 8 | AK17: 75 | AL17: 190 | AM17: 1.52
A18: 30 tom /------ | B18: 24 | C18: 26.91 | D18: 44.583 | E18: 1.07 | K18: 30 tom /------ | L18: 26 | M18: 30.192 | N18: 51.1538 | O18: 1.33 | U18: 30 tom /------ | V18: 23 | W18: 44.5 | X18: 80.4 | Y18: 1.85 | AE18: 30 tom /------ | AF18: 22 | AG18: 42.045454 | AH18: 88.1818 | AI18: 1.94
A20: note- data for each monoculture pot must be entered in two places above
L21: ** one group potted 10 T / 20 A instead of 10 O/ 20 A -- so 10 T/20 A was duplicated

Sheet Th2-5
E1: Room 2114 | J1: | | O1: Room 2122 | T1: | | Y1: Room 2115 | AD1: | | AI1: Room 2123
